Workbook
Name NativeTimeline_Date: #N/A
Name Slicer_Day_Type: #N/A
Name Slicer_Day_Type1: #N/A
Name Slicer_Weather_Code: #N/A

Sheet Table1
A1: instant | B1: dteday | C1: season | D1: yr | E1: mnth | F1: hr | G1: holiday | H1: weekday | I1: weathersit | J1: temp
A2: 1 | B2: 40544 | C2: 1 | D2: 0 | E2: 1 | F2: 0 | G2: FALSE | H2: 6 | I2: 1 | J2: 0.24
A3: 2 | B3: 40544 | C3: 1 | D3: 0 | E3: 1 | F3: 1 | G3: FALSE | H3: 6 | I3: 1 | J3: 0.22
A4: 3 | B4: 40544 | C4: 1 | D4: 0 | E4: 1 | F4: 2 | G4: FALSE | H4: 6 | I4: 1 | J4: 0.22
A5: 4 | B5: 40544 | C5: 1 | D5: 0 | E5: 1 | F5: 3 | G5: FALSE | H5: 6 | I5: 1 | J5: 0.24
A6: 5 | B6: 40544 | C6: 1 | D6: 0 | E6: 1 | F6: 4 | G6: FALSE | H6: 6 | I6: 1 | J6: 0.24
A7: 6 | B7: 40544 | C7: 1 | D7: 0 | E7: 1 | F7: 5 | G7: FALSE | H7: 6 | I7: 2 | J7: 0.24
A8: 7 | B8: 40544 | C8: 1 | D8: 0 | E8: 1 | F8: 6 | G8: FALSE | H8: 6 | I8: 1 | J8: 0.22
A9: 8 | B9: 40544 | C9: 1 | D9: 0 | E9: 1 | F9: 7 | G9: FALSE | H9: 6 | I9: 1 | J9: 0.2
A10: 9 | B10: 40544 | C10: 1 | D10: 0 | E10: 1 | F10: 8 | G10: FALSE | H10: 6 | I10: 1 | J10: 0.24
A11: 10 | B11: 40544 | C11: 1 | D11: 0 | E11: 1 | F11: 9 | G11: FALSE | H11: 6 | I11: 1 | J11: 0.32
A12: 11 | B12: 40544 | C12: 1 | D12: 0 | E12: 1 | F12: 10 | G12: FALSE | H12: 6 | I12: 1 | J12: 0.38
A13: 12 | B13: 40544 | C13: 1 | D13: 0 | E13: 1 | F13: 11 | G13: FALSE | H13: 6 | I13: 1 | J13: 0.36
... A611: 610 | B611: 40571 | C611: 1 | D611: 0 | E611: 1 | F611: 15 | G611: FALSE | H611: 5 | I611: 2 | J611: 0.2

Sheet Cleaned_dataset_1
A1: instant | B1: dteday | C1: season | D1: yr | E1: mnth | F1: hr | G1: holiday | H1: weekday | I1: weathersit | J1: temp
A2: 1 | B2: 40544 | C2: 1 | D2: 0 | E2: 1 | F2: 0 | G2: FALSE | H2: 6 | I2: 1 | J2: 0.24
A3: 2 | B3: 40544 | C3: 1 | D3: 0 | E3: 1 | F3: 1 | G3: FALSE | H3: 6 | I3: 1 | J3: 0.22
A4: 3 | B4: 40544 | C4: 1 | D4: 0 | E4: 1 | F4: 2 | G4: FALSE | H4: 6 | I4: 1 | J4: 0.22
A5: 4 | B5: 40544 | C5: 1 | D5: 0 | E5: 1 | F5: 3 | G5: FALSE | H5: 6 | I5: 1 | J5: 0.24
A6: 5 | B6: 40544 | C6: 1 | D6: 0 | E6: 1 | F6: 4 | G6: FALSE | H6: 6 | I6: 1 | J6: 0.24
A7: 6 | B7: 40544 | C7: 1 | D7: 0 | E7: 1 | F7: 5 | G7: FALSE | H7: 6 | I7: 2 | J7: 0.24
A8: 7 | B8: 40544 | C8: 1 | D8: 0 | E8: 1 | F8: 6 | G8: FALSE | H8: 6 | I8: 1 | J8: 0.22
A9: 8 | B9: 40544 | C9: 1 | D9: 0 | E9: 1 | F9: 7 | G9: FALSE | H9: 6 | I9: 1 | J9: 0.2
A10: 9 | B10: 40544 | C10: 1 | D10: 0 | E10: 1 | F10: 8 | G10: FALSE | H10: 6 | I10: 1 | J10: 0.24
A11: 10 | B11: 40544 | C11: 1 | D11: 0 | E11: 1 | F11: 9 | G11: FALSE | H11: 6 | I11: 1 | J11: 0.32
A12: 11 | B12: 40544 | C12: 1 | D12: 0 | E12: 1 | F12: 10 | G12: FALSE | H12: 6 | I12: 1 | J12: 0.38
A13: 12 | B13: 40544 | C13: 1 | D13: 0 | E13: 1 | F13: 11 | G13: FALSE | H13: 6 | I13: 1 | J13: 0.36
... A611: 610 | B611: 40571 | C611: 1 | D611: 0 | E611: 1 | F611: 15 | G611: FALSE | H611: 5 | I611: 2 | J611: 0.2

Sheet Merge1
A1: instant | B1: dteday | C1: season | D1: yr | E1: mnth | F1: hr | G1: holiday | H1: weekday | I1: weathersit | J1: temp
A2: 1 | B2: 40544 | C2: 1 | D2: 0 | E2: 1 | F2: 0 | G2: FALSE | H2: 6 | I2: 1 | J2: 0.24
A3: 2 | B3: 40544 | C3: 1 | D3: 0 | E3: 1 | F3: 1 | G3: FALSE | H3: 6 | I3: 1 | J3: 0.22
A4: 3 | B4: 40544 | C4: 1 | D4: 0 | E4: 1 | F4: 2 | G4: FALSE | H4: 6 | I4: 1 | J4: 0.22
A5: 4 | B5: 40544 | C5: 1 | D5: 0 | E5: 1 | F5: 3 | G5: FALSE | H5: 6 | I5: 1 | J5: 0.24
A6: 5 | B6: 40544 | C6: 1 | D6: 0 | E6: 1 | F6: 4 | G6: FALSE | H6: 6 | I6: 1 | J6: 0.24
A7: 6 | B7: 40544 | C7: 1 | D7: 0 | E7: 1 | F7: 5 | G7: FALSE | H7: 6 | I7: 2 | J7: 0.24
A8: 7 | B8: 40544 | C8: 1 | D8: 0 | E8: 1 | F8: 6 | G8: FALSE | H8: 6 | I8: 1 | J8: 0.22
A9: 8 | B9: 40544 | C9: 1 | D9: 0 | E9: 1 | F9: 7 | G9: FALSE | H9: 6 | I9: 1 | J9: 0.2
A10: 9 | B10: 40544 | C10: 1 | D10: 0 | E10: 1 | F10: 8 | G10: FALSE | H10: 6 | I10: 1 | J10: 0.24
A11: 10 | B11: 40544 | C11: 1 | D11: 0 | E11: 1 | F11: 9 | G11: FALSE | H11: 6 | I11: 1 | J11: 0.32
A12: 11 | B12: 40544 | C12: 1 | D12: 0 | E12: 1 | F12: 10 | G12: FALSE | H12: 6 | I12: 1 | J12: 0.38
A13: 12 | B13: 40544 | C13: 1 | D13: 0 | E13: 1 | F13: 11 | G13: FALSE | H13: 6 | I13: 1 | J13: 0.36
... A611: 610 | B611: 40571 | C611: 1 | D611: 0 | E611: 1 | F611: 15 | G611: FALSE | H611: 5 | I611: 2 | J611: 0.2

Sheet Cleaned_Dataset_2
A1: instant | B1: atemp | C1: hum | D1: windspeed | E1: casual | F1: registered | G1: cnt
A2: 1 | B2: 0.2879 | C2: 0.81 | D2: 0 | E2: 3 | F2: 13 | G2: 16
A3: 2 | B3: 0.2727 | C3: 0.8 | D3: 0 | E3: 8 | F3: 32 | G3: 40
A4: 3 | B4: 0.2727 | C4: 0.8 | D4: 0 | E4: 5 | F4: 27 | G4: 32
A5: 4 | B5: 0.2879 | C5: 0.75 | D5: 0 | E5: 3 | F5: 10 | G5: 13
A6: 5 | B6: 0.2879 | C6: 0.75 | D6: 0 | E6: 0 | F6: 1 | G6: 1
A7: 6 | B7: 0.2576 | C7: 0.75 | D7: 0.0896 | E7: 0 | F7: 1 | G7: 1
A8: 7 | B8: 0.2727 | C8: 0.8 | D8: 0 | E8: 2 | F8: 0 | G8: 2
A9: 8 | B9: 0.2576 | C9: 0.86 | D9: 0 | E9: 1 | F9: 2 | G9: 3
A10: 9 | C10: 0.75 | D10: 0 | E10: 1 | F10: 7 | G10: 8
A11: 10 | B11: 0.3485 | C11: 0.76 | D11: 0 | E11: 8 | F11: 6 | G11: 14
A12: 11 | B12: 0.3939 | C12: 0.76 | D12: 0.2537 | E12: 12 | F12: 24 | G12: 36
A13: 12 | B13: 0.3333 | C13: 0.81 | D13: 0.2836 | E13: 26 | F13: 30 | G13: 56
A14: 13 | B14: 0.4242 | C14: 0.77 | D14: 0.2836 | E14: 29 | F14: 55 | G14: 84
A15: 14 | B15: 0.4545 | C15: 0.72 | D15: 0.2985 | E15: 47 | F15: 47 | G15: 94
A16: 15 | B16: 0.4545 | C16: 0.72 | D16: 0.2836 | E16: 35 | F16: 71 | G16: 106
A17: 16 | B17: 0.4394 | C17: 0.77 | D17: 0.2985 | E17: 40 | F17: 70 | G17: 110
A18: 17 | B18: 0.4242 | C18: 0.82 | D18: 0.2985 | E18: 41 | F18: 52 | G18: 93
A19: 18 | C19: 0.82 | D19: 0.2836 | E19: 15 | F19: 52 | G19: 67
A20: 19 | B20: 0.4242 | C20: 0.88 | D20: 0.2537 | E20: 9 | F20: 26 | G20: 35
A21: 20 | B21: 0.4242 | C21: 0.88 | D21: 0.2537 | E21: 6 | F21: 31 | G21: 37
A22: 21 | B22: 0.4091 | C22: 0.87 | D22: 0.2537 | E22: 11 | F22: 25 | G22: 36
A23: 22 | B23: 0.4091 | C23: 0.87 | D23: 0.194 | E23: 3 | F23: 31 | G23: 34
A24: 23 | B24: 0.4091 | C24: 0.94 | D24: 0.2239 | E24: 11 | F24: 17 | G24: 28
A25: 24 | C25: 0.88 | D25: 0.2985 | E25: 15 | F25: 24 | G25: 39
A26: 25 | B26: 0.4545 | C26: 0.88 | D26: 0.2985 | E26: 4 | F26: 13 | G26: 17
A27: 26 | B27: 0.4394 | C27: 0.94 | D27: 0.2537 | E27: 1 | F27: 16 | G27: 17
A28: 27 | B28: 0.4242 | C28: 1 | D28: 0.2836 | E28: 1 | F28: 8 | G28: 9
A29: 28 | B29: 0.4545 | C29: 0.94 | D29: 0.194 | E29: 2 | F29: 4 | G29: 6
A30: 29 | C30: 0.94 | D30: 0.194 | E30: 2 | F30: 1 | G30: 3
A31: 30 | B31: 0.4242 | C31: 0.77 | D31: 0.2985 | E31: 0 | F31: 2 | G31: 2
A32: 31 | B32: 0.4091 | C32: 0.76 | D32: 0.194 | E32: 0 | F32: 1 | G32: 1
A33: 32 | B33: 0.4091 | C33: 0.71 | D33: 0.2239 | E33: 0 | F33: 8 | G33: 8
A34: 33 | C34: 0.76 | D34: 0.2239 | E34: 1 | F34: 19 | G34: 20
A35: 34 | B35: 0.3485 | C35: 0.81 | D35: 0.2239 | E35: 7 | F35: 46 | G35: 53
A36: 35 | B36: 0.3333 | C36: 0.71 | D36: 0.2537 | E36: 16 | F36: 54 | G36: 70
A37: 36 | B37: 0.3333 | C37: 0.66 | D37: 0.2985 | E37: 20 | F37: 73 | G37: 93
A38: 37 | B38: 0.3485 | C38: 0.66 | D38: 0.1343 | E38: 11 | F38: 64 | G38: 75
A39: 38 | C39: 0.76 | D39: 0.194 | E39: 4 | F39: 55 | G39: 59
A40: 39 | B40: 0.3333 | C40: 0.81 | D40: 0.1642 | E40: 19 | F40: 55 | G40: 74
...

Sheet Cleaned_dataset_3
A1: instant | B1: dteday | C1: season | D1: yr | E1: mnth | F1: hr | G1: holiday | H1: weekday | I1: weathersit | J1: temp | K1: atemp | L1: hum | M1: windspeed | N1: casual | O1: registered | P1: cnt
A2: 620 | B2: 40572 | C2: 1 | D2: 0 | E2: 1 | F2: 1 | G2: FALSE | H2: 6 | I2: 1 | J2: 0.22 | K2: 0.2273 | L2: 0.64 | M2: 0.194 | N2: 0 | O2: 20 | P2: 20
A3: 621 | B3: 40572 | C3: 1 | D3: 0 | E3: 1 | F3: 2 | G3: FALSE | H3: 6 | I3: 1 | J3: 0.22 | K3: 0.2273 | L3: 0.64 | M3: 0.1642 | N3: 0 | O3: 15 | P3: 15
A4: 622 | B4: 40572 | C4: 1 | D4: 0 | E4: 1 | F4: 3 | G4: FALSE | H4: 6 | I4: 1 | J4: 0.2 | K4: 0.2121 | L4: 0.64 | M4: 0.1343 | N4: 3 | O4: 5 | P4: 8
A5: 623 | B5: 40572 | C5: 1 | D5: 0 | E5: 1 | F5: 4 | G5: FALSE | H5: 6 | I5: 1 | J5: 0.16 | K5: 0.1818 | L5: 0.69 | M5: 0.1045 | N5: 1 | O5: 2 | P5: 3
A6: 624 | B6: 40572 | C6: 1 | D6: 0 | E6: 1 | F6: 6 | G6: FALSE | H6: 6 | I6: 1 | J6: 0.16 | K6: 0.1818 | L6: 0.64 | M6: 0.1343 | N6: 0 | O6: 2 | P6: 2
A7: 625 | B7: 40572 | C7: 1 | D7: 0 | E7: 1 | F7: 7 | G7: FALSE | H7: 6 | I7: 1 | J7: 0.16 | K7: 0.1818 | L7: 0.59 | M7: 0.1045 | N7: 1 | O7: 4 | P7: 5
A8: 626 | B8: 40572 | C8: 1 | D8: 0 | E8: 1 | F8: 8 | G8: FALSE | H8: 6 | I8: 1 | J8: 0.18 | K8: 0.197 | L8: 0.55 | M8: 0.1642 | N8: 3 | O8: 31 | P8: 34
A9: 627 | B9: 40572 | C9: 1 | D9: 0 | E9: 1 | F9: 9 | G9: FALSE | H9: 6 | I9: 1 | J9: 0.18 | K9: 0.2121 | L9: 0.59 | M9: 0.0896 | N9: 0 | O9: 34 | P9: 34
A10: 628 | B10: 40572 | C10: 1 | D10: 0 | E10: 1 | F10: 10 | G10: FALSE | H10: 6 | I10: 2 | J10: 0.18 | K10: 0.2121 | L10: 0.64 | M10: 0.1045 | N10: 4 | O10: 51 | P10: 55
A11: 629 | B11: 40572 | C11: 1 | D11: 0 | E11: 1 | F11: 11 | G11: FALSE | H11: 6 | I11: 2 | J11: 0.18 | K11: 0.197 | L11: 0.64 | M11: 0.1343 | N11: 4 | O11: 60 | P11: 64
A12: 630 | B12: 40572 | C12: 1 | D12: 0 | E12: 1 | F12: 12 | G12: FALSE | H12: 6 | I12: 2 | J12: 0.2 | K12: 0.197 | L12: 0.59 | M12: 0.194 | N12: 12 | O12: 66 | P12: 78
A13: 631 | B13: 40572 | C13: 1 | D13: 0 | E13: 1 | F13: 13 | G13: FALSE | H13: 6 | I13: 2 | J13: 0.22 | K13: 0.2273 | L13: 0.55 | M13: 0.1642 | N13: 9 | O13: 56 | P13: 65
... A391: 619 | B391: 40572 | C391: 1 | D391: 0 | E391: 1 | F391: 0 | G391: FALSE | H391: 6 | I391: 1 | J391: 0.22 | K391: 0.197 | L391: 0.64 | M391: 0.3582 | N391: 2 | O391: 26 | P391: 28

Sheet cleaned_dataset A
A1: Record_Id | B1: Date | C1: Season_Code | D1: Year | E1: Month | F1: Hour | G1: Holiday | H1: Day_Code | I1: Day_Type | J1: Weather_Code | K1: Temperature | L1: Assumed_Temperature | M1: Humidity | N1: Wind_Speed | O1: Casual_Rentals | P1: Registered_Rentals | Q1: Total_Rentals | R1: Weather_Description
A2: 1 | B2: 40544 | C2: winter | D2: 0 | E2: January | F2: 0 | G2: FALSE | H2: 6 | I2: Saturday | J2: 1 | K2: 0.24 | L2: 0.2879 | M2: 0.81 | N2: 0 | O2: 3 | P2: 13 | Q2: =SUM(Append1[[#This Row],[Casual_Rentals]],Append1[[#This Row],[Registered_Rentals]]) -> 16 | R2: Clear
A3: 2 | B3: 40544 | C3: winter | D3: 0 | E3: January | F3: 1 | G3: FALSE | H3: 6 | I3: Saturday | J3: 1 | K3: 0.22 | L3: 0.2727 | M3: 0.8 | N3: 0 | O3: 8 | P3: 32 | Q3: =SUM(Append1[[#This Row],[Casual_Rentals]],Append1[[#This Row],[Registered_Rentals]]) -> 40 | R3: Clear
A4: 3 | B4: 40544 | C4: winter | D4: 0 | E4: January | F4: 2 | G4: FALSE | H4: 6 | I4: Saturday | J4: 1 | K4: 0.22 | L4: 0.2727 | M4: 0.8 | N4: 0 | O4: 5 | P4: 27 | Q4: =SUM(Append1[[#This Row],[Casual_Rentals]],Append1[[#This Row],[Registered_Rentals]]) -> 32 | R4: Clear
A5: 4 | B5: 40544 | C5: winter | D5: 0 | E5: January | F5: 3 | G5: FALSE | H5: 6 | I5: Saturday | J5: 1 | K5: 0.24 | L5: 0.2879 | M5: 0.75 | N5: 0 | O5: 3 | P5: 10 | Q5: =SUM(Append1[[#This Row],[Casual_Rentals]],Append1[[#This Row],[Registered_Rentals]]) -> 13 | R5: Clear
A6: 5 | B6: 40544 | C6: winter | D6: 0 | E6: January | F6: 4 | G6: FALSE | H6: 6 | I6: Saturday | J6: 1 | K6: 0.24 | L6: 0.2879 | M6: 0.75 | N6: 0 | O6: 0 | P6: 1 | Q6: =SUM(Append1[[#This Row],[Casual_Rentals]],Append1[[#This Row],[Registered_Rentals]]) -> 1 | R6: Clear
A7: 6 | B7: 40544 | C7: winter | D7: 0 | E7: January | F7: 5 | G7: FALSE | H7: 6 | I7: Saturday | J7: 2 | K7: 0.24 | L7: 0.2576 | M7: 0.75 | N7: 0.0896 | O7: 0 | P7: 1 | Q7: =SUM(Append1[[#This Row],[Casual_Rentals]],Append1[[#This Row],[Registered_Rentals]]) -> 1 | R7: Cloudy
A8: 7 | B8: 40544 | C8: winter | D8: 0 | E8: January | F8: 6 | G8: FALSE | H8: 6 | I8: Saturday | J8: 1 | K8: 0.22 | L8: 0.2727 | M8: 0.8 | N8: 0 | O8: 2 | P8: 0 | Q8: =SUM(Append1[[#This Row],[Casual_Rentals]],Append1[[#This Row],[Registered_Rentals]]) -> 2 | R8: Clear
A9: 8 | B9: 40544 | C9: winter | D9: 0 | E9: January | F9: 7 | G9: FALSE | H9: 6 | I9: Saturday | J9: 1 | K9: 0.2 | L9: 0.2576 | M9: 0.86 | N9: 0 | O9: 1 | P9: 2 | Q9: =SUM(Append1[[#This Row],[Casual_Rentals]],Append1[[#This Row],[Registered_Rentals]]) -> 3 | R9: Clear
A10: 9 | B10: 40544 | C10: winter | D10: 0 | E10: January | F10: 8 | G10: FALSE | H10: 6 | I10: Saturday | J10: 1 | K10: 0.24 | L10: 0.2576 | M10: 0.75 | N10: 0 | O10: 1 | P10: 7 | Q10: =SUM(Append1[[#This Row],[Casual_Rentals]],Append1[[#This Row],[Registered_Rentals]]) -> 8 | R10: Clear
A11: 10 | B11: 40544 | C11: winter | D11: 0 | E11: January | F11: 9 | G11: FALSE | H11: 6 | I11: Saturday | J11: 1 | K11: 0.32 | L11: 0.3485 | M11: 0.76 | N11: 0 | O11: 8 | P11: 6 | Q11: =SUM(Append1[[#This Row],[Casual_Rentals]],Append1[[#This Row],[Registered_Rentals]]) -> 14 | R11: Clear
A12: 11 | B12: 40544 | C12: winter | D12: 0 | E12: January | F12: 10 | G12: FALSE | H12: 6 | I12: Saturday | J12: 1 | K12: 0.38 | L12: 0.3939 | M12: 0.76 | N12: 0.2537 | O12: 12 | P12: 24 | Q12: =SUM(Append1[[#This Row],[Casual_Rentals]],Append1[[#This Row],[Registered_Rentals]]) -> 36 | R12: Clear
A13: 12 | B13: 40544 | C13: winter | D13: 0 | E13: January | F13: 11 | G13: FALSE | H13: 6 | I13: Saturday | J13: 1 | K13: 0.36 | L13: 0.3333 | M13: 0.81 | N13: 0.2836 | O13: 26 | P13: 30 | Q13: =SUM(Append1[[#This Row],[Casual_Rentals]],Append1[[#This Row],[Registered_Rentals]]) -> 56 | R13: Clear
... A611: 610 | B611: 40571 | C611: winter | D611: 0 | E611: January | F611: 15 | G611: FALSE | H611: 5 | I611: Friday | J611: 2 | K611: 0.2 | L611: 0.2576 | M611: 0.86 | N611: 0 | O611: 1 | P611: 40 | Q611: =SUM(Append1[[#This Row],[Casual_Rentals]],Append1[[#This Row],[Registered_Rentals]]) -> 41 | R611: Cloudy
A612: 611 | B612: 40571 | C612: winter | D612: 0 | E612: January | F612: 16 | G612: FALSE | H612: 5 | I612: Friday | J612: 1 | K612: 0.22 | L612: 0.2727 | M612: 0.8 | N612: 0 | O612: 10 | P612: 70 | Q612: 80 | R612: Clear
A613: 612 | B613: 40571 | C613: winter | D613: 0 | E613: January | F613: 17 | G613: FALSE | H613: 5 | I613: Friday | J613: 1 | K613: 0.24 | L613: 0.2424 | M613: 0.75 | N613: 0.1343 | O613: 2 | P613: 147 | Q613: 149 | R613: Clear
A614: 613 | B614: 40571 | C614: winter | D614: 0 | E614: January | F614: 18 | G614: FALSE | H614: 5 | I614: Friday | J614: 1 | K614: 0.24 | L614: 0.2273 | M614: 0.75 | N614: 0.194 | O614: 2 | P614: 107 | Q614: 109 | R614: Clear
A615: 614 | B615: 40571 | C615: winter | D615: 0 | E615: January | F615: 19 | G615: FALSE | H615: 5 | I615: Friday | J615: 2 | K615: 0.24 | L615: 0.2424 | M615: 0.75 | N615: 0.1343 | O615: 5 | P615: 84 | Q615: 89 | R615: Cloudy
A616: 615 | B616: 40571 | C616: winter | D616: 0 | E616: January | F616: 20 | G616: FALSE | H616: 5 | I616: Friday | J616: 2 | K616: 0.24 | L616: 0.2273 | M616: 0.7 | N616: 0.194 | O616: 1 | P616: 61 | Q616: 62 | R616: Cloudy
A617: 616 | B617: 40571 | C617: winter | D617: 0 | E617: January | F617: 21 | G617: FALSE | H617: 5 | I617: Friday | J617: 2 | K617: 0.22 | L617: 0.2273 | M617: 0.75 | N617: 0.1343 | O617: 1 | P617: 57 | Q617: 58 | R617: Cloudy
A618: 617 | B618: 40571 | C618: winter | D618: 0 | E618: January | F618: 22 | G618: FALSE | H618: 5 | I618: Friday | J618: 1 | K618: 0.24 | L618: 0.2121 | M618: 0.65 | N618: 0.3582 | O618: 0 | P618: 26 | Q618: 26 | R618: Clear
A619: 618 | B619: 40571 | C619: winter | D619: 0 | E619: January | F619: 23 | G619: FALSE | H619: 5 | I619: Friday | J619: 1 | K619: 0.24 | L619: 0.2273 | M619: 0.6 | N619: 0.2239 | O619: 1 | P619: 22 | Q619: 23 | R619: Clear
A620: 619 | B620: 40572 | C620: winter | D620: 0 | E620: January | F620: 0 | G620: FALSE | H620: 6 | I620: Saturday | J620: 1 | K620: 0.22 | L620: 0.197 | M620: 0.64 | N620: 0.3582 | O620: 2 | P620: 26 | Q620: 28 | R620: Clear
A621: 620 | B621: 40572 | C621: winter | D621: 0 | E621: January | F621: 1 | G621: FALSE | H621: 6 | I621: Saturday | J621: 1 | K621: 0.22 | L621: 0.2273 | M621: 0.64 | N621: 0.194 | O621: 0 | P621: 20 | Q621: 20 | R621: Clear
A622: 621 | B622: 40572 | C622: winter | D622: 0 | E622: January | F622: 2 | G622: FALSE | H622: 6 | I622: Saturday | J622: 1 | K622: 0.22 | L622: 0.2273 | M622: 0.64 | N622: 0.1642 | O622: 0 | P622: 15 | Q622: 15 | R622: Clear
A623: 622 | B623: 40572 | C623: winter | D623: 0 | E623: January | F623: 3 | G623: FALSE | H623: 6 | I623: Saturday | J623: 1 | K623: 0.2 | L623: 0.2121 | M623: 0.64 | N623: 0.1343 | O623: 3 | P623: 5 | Q623: 8 | R623: Clear
... A1001: 1000 | B1001: 40588 | C1001: winter | D1001: 0 | E1001: February | F1001: 7 | G1001: FALSE | H1001: 1 | I1001: Monday | J1001: 1 | K1001: 0.34 | L1001: 0.303 | M1001: 0.46 | N1001: 0.2985 | O1001: 2 | P1001: 96 | Q1001: 98 | R1001: Clear

Sheet Sheet13
A1: Date | B1: Total_Rentals | C1: Forecast(Total_Rentals) | D1: Lower Confidence Bound(Total_Rentals) | E1: Upper Confidence Bound(Total_Rentals)
A2: 40544 | B2: 41.041667
A3: 40545 | B3: 34.826087
A4: 40546 | B4: 61.318182
A5: 40547 | B5: 67.913043
A6: 40548 | B6: 69.565217
A7: 40549 | B7: 69.826087
A8: 40550 | B8: 65.652174
A9: 40551 | B9: 39.958333
A10: 40552 | B10: 34.25
A11: 40553 | B11: 55.041667
A12: 40554 | B12: 57.409091
A13: 40555 | B13: 52.818182
... A45: 40587 | B45: 69.086957
A46: 40588 | B46: 18.875 | C46: 18.875 | D46: 18.875 | E46: 18.875
A47: 40589 | C47: =_xlfn.FORECAST.ETS(A47,$B$2:$B$46,$A$2:$A$46,1,1) -> 61.270134 | D47: =C47-_xlfn.FORECAST.ETS.CONFINT(A47,$B$2:$B$46,$A$2:$A$46,0.95,1,1) -> 31.858656 | E47: =C47+_xlfn.FORECAST.ETS.CONFINT(A47,$B$2:$B$46,$A$2:$A$46,0.95,1,1) -> 90.681612
A48: 40590 | C48: =_xlfn.FORECAST.ETS(A48,$B$2:$B$46,$A$2:$A$46,1,1) -> 61.525828 | D48: =C48-_xlfn.FORECAST.ETS.CONFINT(A48,$B$2:$B$46,$A$2:$A$46,0.95,1,1) -> 31.878109 | E48: =C48+_xlfn.FORECAST.ETS.CONFINT(A48,$B$2:$B$46,$A$2:$A$46,0.95,1,1) -> 91.173546
A49: 40591 | C49: =_xlfn.FORECAST.ETS(A49,$B$2:$B$46,$A$2:$A$46,1,1) -> 61.781521 | D49: =C49-_xlfn.FORECAST.ETS.CONFINT(A49,$B$2:$B$46,$A$2:$A$46,0.95,1,1) -> 31.89574 | E49: =C49+_xlfn.FORECAST.ETS.CONFINT(A49,$B$2:$B$46,$A$2:$A$46,0.95,1,1) -> 91.667303
A50: 40592 | C50: =_xlfn.FORECAST.ETS(A50,$B$2:$B$46,$A$2:$A$46,1,1) -> 62.037215 | D50: =C50-_xlfn.FORECAST.ETS.CONFINT(A50,$B$2:$B$46,$A$2:$A$46,0.95,1,1) -> 31.911562 | E50: =C50+_xlfn.FORECAST.ETS.CONFINT(A50,$B$2:$B$46,$A$2:$A$46,0.95,1,1) -> 92.162868
A51: 40593 | C51: =_xlfn.FORECAST.ETS(A51,$B$2:$B$46,$A$2:$A$46,1,1) -> 62.292909 | D51: =C51-_xlfn.FORECAST.ETS.CONFINT(A51,$B$2:$B$46,$A$2:$A$46,0.95,1,1) -> 31.925589 | E51: =C51+_xlfn.FORECAST.ETS.CONFINT(A51,$B$2:$B$46,$A$2:$A$46,0.95,1,1) -> 92.660228
A52: 40594 | C52: =_xlfn.FORECAST.ETS(A52,$B$2:$B$46,$A$2:$A$46,1,1) -> 62.548602 | D52: =C52-_xlfn.FORECAST.ETS.CONFINT(A52,$B$2:$B$46,$A$2:$A$46,0.95,1,1) -> 31.937837 | E52: =C52+_xlfn.FORECAST.ETS.CONFINT(A52,$B$2:$B$46,$A$2:$A$46,0.95,1,1) -> 93.159367
A53: 40595 | C53: =_xlfn.FORECAST.ETS(A53,$B$2:$B$46,$A$2:$A$46,1,1) -> 62.804296 | D53: =C53-_xlfn.FORECAST.ETS.CONFINT(A53,$B$2:$B$46,$A$2:$A$46,0.95,1,1) -> 31.948319 | E53: =C53+_xlfn.FORECAST.ETS.CONFINT(A53,$B$2:$B$46,$A$2:$A$46,0.95,1,1) -> 93.660273
A54: 40596 | C54: =_xlfn.FORECAST.ETS(A54,$B$2:$B$46,$A$2:$A$46,1,1) -> 63.05999 | D54: =C54-_xlfn.FORECAST.ETS.CONFINT(A54,$B$2:$B$46,$A$2:$A$46,0.95,1,1) -> 31.957049 | E54: =C54+_xlfn.FORECAST.ETS.CONFINT(A54,$B$2:$B$46,$A$2:$A$46,0.95,1,1) -> 94.16293
A55: 40597 | C55: =_xlfn.FORECAST.ETS(A55,$B$2:$B$46,$A$2:$A$46,1,1) -> 63.315683 | D55: =C55-_xlfn.FORECAST.ETS.CONFINT(A55,$B$2:$B$46,$A$2:$A$46,0.95,1,1) -> 31.964041 | E55: =C55+_xlfn.FORECAST.ETS.CONFINT(A55,$B$2:$B$46,$A$2:$A$46,0.95,1,1) -> 94.667326
A56: 40598 | C56: =_xlfn.FORECAST.ETS(A56,$B$2:$B$46,$A$2:$A$46,1,1) -> 63.571377 | D56: =C56-_xlfn.FORECAST.ETS.CONFINT(A56,$B$2:$B$46,$A$2:$A$46,0.95,1,1) -> 31.969308 | E56: =C56+_xlfn.FORECAST.ETS.CONFINT(A56,$B$2:$B$46,$A$2:$A$46,0.95,1,1) -> 95.173446
A57: 40599 | C57: =_xlfn.FORECAST.ETS(A57,$B$2:$B$46,$A$2:$A$46,1,1) -> 63.82707 | D57: =C57-_xlfn.FORECAST.ETS.CONFINT(A57,$B$2:$B$46,$A$2:$A$46,0.95,1,1) -> 31.972864 | E57: =C57+_xlfn.FORECAST.ETS.CONFINT(A57,$B$2:$B$46,$A$2:$A$46,0.95,1,1) -> 95.681276
A58: 40600 | C58: =_xlfn.FORECAST.ETS(A58,$B$2:$B$46,$A$2:$A$46,1,1) -> 64.082764 | D58: =C58-_xlfn.FORECAST.ETS.CONFINT(A58,$B$2:$B$46,$A$2:$A$46,0.95,1,1) -> 31.974723 | E58: =C58+_xlfn.FORECAST.ETS.CONFINT(A58,$B$2:$B$46,$A$2:$A$46,0.95,1,1) -> 96.190805

Sheet Sheet14
A1: Date | B1: Casual_Rentals | C1: Forecast(Casual_Rentals) | D1: Lower Confidence Bound(Casual_Rentals) | E1: Upper Confidence Bound(Casual_Rentals)
A2: 40544 | B2: 13.791667
A3: 40545 | B3: 5.6956522
A4: 40546 | B4: 5.4545455
A5: 40547 | B5: 4.6956522
A6: 40548 | B6: 3.5652174
A7: 40549 | B7: 3.826087
A8: 40550 | B8: 6.4347826
A9: 40551 | B9: 2.8333333
A10: 40552 | B10: 2.25
A11: 40553 | B11: 1.7083333
A12: 40554 | B12: 1.9545455
A13: 40555 | B13: 1.1363636
... A45: 40587 | B45: 17.26087
A46: 40588 | B46: 1 | C46: 1 | D46: 1 | E46: 1
A47: 40589 | C47: =_xlfn.FORECAST.ETS(A47,$B$2:$B$46,$A$2:$A$46,1,1) -> 4.8565291 | D47: =C47-_xlfn.FORECAST.ETS.CONFINT(A47,$B$2:$B$46,$A$2:$A$46,0.95,1,1) -> -1.964803 | E47: =C47+_xlfn.FORECAST.ETS.CONFINT(A47,$B$2:$B$46,$A$2:$A$46,0.95,1,1) -> 11.677861
A48: 40590 | C48: =_xlfn.FORECAST.ETS(A48,$B$2:$B$46,$A$2:$A$46,1,1) -> 4.9858123 | D48: =C48-_xlfn.FORECAST.ETS.CONFINT(A48,$B$2:$B$46,$A$2:$A$46,0.95,1,1) -> -2.6467798 | E48: =C48+_xlfn.FORECAST.ETS.CONFINT(A48,$B$2:$B$46,$A$2:$A$46,0.95,1,1) -> 12.618404
A49: 40591 | C49: =_xlfn.FORECAST.ETS(A49,$B$2:$B$46,$A$2:$A$46,1,1) -> 5.2999641 | D49: =C49-_xlfn.FORECAST.ETS.CONFINT(A49,$B$2:$B$46,$A$2:$A$46,0.95,1,1) -> -3.068376 | E49: =C49+_xlfn.FORECAST.ETS.CONFINT(A49,$B$2:$B$46,$A$2:$A$46,0.95,1,1) -> 13.668304
A50: 40592 | C50: =_xlfn.FORECAST.ETS(A50,$B$2:$B$46,$A$2:$A$46,1,1) -> 6.2511965 | D50: =C50-_xlfn.FORECAST.ETS.CONFINT(A50,$B$2:$B$46,$A$2:$A$46,0.95,1,1) -> -2.7958265 | E50: =C50+_xlfn.FORECAST.ETS.CONFINT(A50,$B$2:$B$46,$A$2:$A$46,0.95,1,1) -> 15.29822
A51: 40593 | C51: =_xlfn.FORECAST.ETS(A51,$B$2:$B$46,$A$2:$A$46,1,1) -> 7.6676803 | D51: =C51-_xlfn.FORECAST.ETS.CONFINT(A51,$B$2:$B$46,$A$2:$A$46,0.95,1,1) -> -2.0129749 | E51: =C51+_xlfn.FORECAST.ETS.CONFINT(A51,$B$2:$B$46,$A$2:$A$46,0.95,1,1) -> 17.348335
A52: 40594 | C52: =_xlfn.FORECAST.ETS(A52,$B$2:$B$46,$A$2:$A$46,1,1) -> 8.7400882 | D52: =C52-_xlfn.FORECAST.ETS.CONFINT(A52,$B$2:$B$46,$A$2:$A$46,0.95,1,1) -> -1.5374887 | E52: =C52+_xlfn.FORECAST.ETS.CONFINT(A52,$B$2:$B$46,$A$2:$A$46,0.95,1,1) -> 19.017665
A53: 40595 | C53: =_xlfn.FORECAST.ETS(A53,$B$2:$B$46,$A$2:$A$46,1,1) -> 6.303062 | D53: =C53-_xlfn.FORECAST.ETS.CONFINT(A53,$B$2:$B$46,$A$2:$A$46,0.95,1,1) -> -4.5407945 | E53: =C53+_xlfn.FORECAST.ETS.CONFINT(A53,$B$2:$B$46,$A$2:$A$46,0.95,1,1) -> 17.146918
A54: 40596 | C54: =_xlfn.FORECAST.ETS(A54,$B$2:$B$46,$A$2:$A$46,1,1) -> 4.9656242 | D54: =C54-_xlfn.FORECAST.ETS.CONFINT(A54,$B$2:$B$46,$A$2:$A$46,0.95,1,1) -> -6.4205257 | E54: =C54+_xlfn.FORECAST.ETS.CONFINT(A54,$B$2:$B$46,$A$2:$A$46,0.95,1,1) -> 16.351774
A55: 40597 | C55: =_xlfn.FORECAST.ETS(A55,$B$2:$B$46,$A$2:$A$46,1,1) -> 5.0949073 | D55: =C55-_xlfn.FORECAST.ETS.CONFINT(A55,$B$2:$B$46,$A$2:$A$46,0.95,1,1) -> -6.8088567 | E55: =C55+_xlfn.FORECAST.ETS.CONFINT(A55,$B$2:$B$46,$A$2:$A$46,0.95,1,1) -> 16.998671
A56: 40598 | C56: =_xlfn.FORECAST.ETS(A56,$B$2:$B$46,$A$2:$A$46,1,1) -> 5.4090591 | D56: =C56-_xlfn.FORECAST.ETS.CONFINT(A56,$B$2:$B$46,$A$2:$A$46,0.95,1,1) -> -6.9926424 | E56: =C56+_xlfn.FORECAST.ETS.CONFINT(A56,$B$2:$B$46,$A$2:$A$46,0.95,1,1) -> 17.810761
A57: 40599 | C57: =_xlfn.FORECAST.ETS(A57,$B$2:$B$46,$A$2:$A$46,1,1) -> 6.3602916 | D57: =C57-_xlfn.FORECAST.ETS.CONFINT(A57,$B$2:$B$46,$A$2:$A$46,0.95,1,1) -> -6.5219562 | E57: =C57+_xlfn.FORECAST.ETS.CONFINT(A57,$B$2:$B$46,$A$2:$A$46,0.95,1,1) -> 19.242539
A58: 40600 | C58: =_xlfn.FORECAST.ETS(A58,$B$2:$B$46,$A$2:$A$46,1,1) -> 7.7767753 | D58: =C58-_xlfn.FORECAST.ETS.CONFINT(A58,$B$2:$B$46,$A$2:$A$46,0.95,1,1) -> -5.5705098 | E58: =C58+_xlfn.FORECAST.ETS.CONFINT(A58,$B$2:$B$46,$A$2:$A$46,0.95,1,1) -> 21.12406
... A60: 40602 | C60: =_xlfn.FORECAST.ETS(A60,$B$2:$B$46,$A$2:$A$46,1,1) -> 6.412157 | D60: =C60-_xlfn.FORECAST.ETS.CONFINT(A60,$B$2:$B$46,$A$2:$A$46,0.95,1,1) -> -7.8247181 | E60: =C60+_xlfn.FORECAST.ETS.CONFINT(A60,$B$2:$B$46,$A$2:$A$46,0.95,1,1) -> 20.649032

Sheet Sheet15
A1: Date | B1: Registered_Rentals | C1: Forecast(Registered_Rentals) | D1: Lower Confidence Bound(Registered_Rentals) | E1: Upper Confidence Bound(Registered_Rentals)
A2: 40544 | B2: 27.25
A3: 40545 | B3: 29.130435
A4: 40546 | B4: 55.863636
A5: 40547 | B5: 63.217391
A6: 40548 | B6: 66
A7: 40549 | B7: 66
A8: 40550 | B8: 59.217391
A9: 40551 | B9: 37.125
A10: 40552 | B10: 32
A11: 40553 | B11: 53.333333
A12: 40554 | B12: 55.454545
A13: 40555 | B13: 51.681818
... A45: 40587 | B45: 51.826087
A46: 40588 | B46: 17.875 | C46: 17.875 | D46: 17.875 | E46: 17.875
A47: 40589 | C47: =_xlfn.FORECAST.ETS(A47,$B$2:$B$46,$A$2:$A$46,1,1) -> 62.26321 | D47: =C47-_xlfn.FORECAST.ETS.CONFINT(A47,$B$2:$B$46,$A$2:$A$46,0.95,1,1) -> 39.903506 | E47: =C47+_xlfn.FORECAST.ETS.CONFINT(A47,$B$2:$B$46,$A$2:$A$46,0.95,1,1) -> 84.622914
A48: 40590 | C48: =_xlfn.FORECAST.ETS(A48,$B$2:$B$46,$A$2:$A$46,1,1) -> 65.743017 | D48: =C48-_xlfn.FORECAST.ETS.CONFINT(A48,$B$2:$B$46,$A$2:$A$46,0.95,1,1) -> 43.203714 | E48: =C48+_xlfn.FORECAST.ETS.CONFINT(A48,$B$2:$B$46,$A$2:$A$46,0.95,1,1) -> 88.282319
A49: 40591 | C49: =_xlfn.FORECAST.ETS(A49,$B$2:$B$46,$A$2:$A$46,1,1) -> 70.334538 | D49: =C49-_xlfn.FORECAST.ETS.CONFINT(A49,$B$2:$B$46,$A$2:$A$46,0.95,1,1) -> 47.614251 | E49: =C49+_xlfn.FORECAST.ETS.CONFINT(A49,$B$2:$B$46,$A$2:$A$46,0.95,1,1) -> 93.054825
A50: 40592 | C50: =_xlfn.FORECAST.ETS(A50,$B$2:$B$46,$A$2:$A$46,1,1) -> 63.501284 | D50: =C50-_xlfn.FORECAST.ETS.CONFINT(A50,$B$2:$B$46,$A$2:$A$46,0.95,1,1) -> 40.598637 | E50: =C50+_xlfn.FORECAST.ETS.CONFINT(A50,$B$2:$B$46,$A$2:$A$46,0.95,1,1) -> 86.40393
A51: 40593 | C51: =_xlfn.FORECAST.ETS(A51,$B$2:$B$46,$A$2:$A$46,1,1) -> 43.905159 | D51: =C51-_xlfn.FORECAST.ETS.CONFINT(A51,$B$2:$B$46,$A$2:$A$46,0.95,1,1) -> 20.818788 | E51: =C51+_xlfn.FORECAST.ETS.CONFINT(A51,$B$2:$B$46,$A$2:$A$46,0.95,1,1) -> 66.991529
A52: 40594 | C52: =_xlfn.FORECAST.ETS(A52,$B$2:$B$46,$A$2:$A$46,1,1) -> 40.807978 | D52: =C52-_xlfn.FORECAST.ETS.CONFINT(A52,$B$2:$B$46,$A$2:$A$46,0.95,1,1) -> 17.536531 | E52: =C52+_xlfn.FORECAST.ETS.CONFINT(A52,$B$2:$B$46,$A$2:$A$46,0.95,1,1) -> 64.079425
A53: 40595 | C53: =_xlfn.FORECAST.ETS(A53,$B$2:$B$46,$A$2:$A$46,1,1) -> 54.228588 | D53: =C53-_xlfn.FORECAST.ETS.CONFINT(A53,$B$2:$B$46,$A$2:$A$46,0.95,1,1) -> 30.770722 | E53: =C53+_xlfn.FORECAST.ETS.CONFINT(A53,$B$2:$B$46,$A$2:$A$46,0.95,1,1) -> 77.686454
A54: 40596 | C54: =_xlfn.FORECAST.ETS(A54,$B$2:$B$46,$A$2:$A$46,1,1) -> 63.66822 | D54: =C54-_xlfn.FORECAST.ETS.CONFINT(A54,$B$2:$B$46,$A$2:$A$46,0.95,1,1) -> 40.01978 | E54: =C54+_xlfn.FORECAST.ETS.CONFINT(A54,$B$2:$B$46,$A$2:$A$46,0.95,1,1) -> 87.316659
A55: 40597 | C55: =_xlfn.FORECAST.ETS(A55,$B$2:$B$46,$A$2:$A$46,1,1) -> 67.148026 | D55: =C55-_xlfn.FORECAST.ETS.CONFINT(A55,$B$2:$B$46,$A$2:$A$46,0.95,1,1) -> 43.310536 | E55: =C55+_xlfn.FORECAST.ETS.CONFINT(A55,$B$2:$B$46,$A$2:$A$46,0.95,1,1) -> 90.985516
A56: 40598 | C56: =_xlfn.FORECAST.ETS(A56,$B$2:$B$46,$A$2:$A$46,1,1) -> 71.739547 | D56: =C56-_xlfn.FORECAST.ETS.CONFINT(A56,$B$2:$B$46,$A$2:$A$46,0.95,1,1) -> 47.711696 | E56: =C56+_xlfn.FORECAST.ETS.CONFINT(A56,$B$2:$B$46,$A$2:$A$46,0.95,1,1) -> 95.767398
A57: 40599 | C57: =_xlfn.FORECAST.ETS(A57,$B$2:$B$46,$A$2:$A$46,1,1) -> 64.906293 | D57: =C57-_xlfn.FORECAST.ETS.CONFINT(A57,$B$2:$B$46,$A$2:$A$46,0.95,1,1) -> 40.68678 | E57: =C57+_xlfn.FORECAST.ETS.CONFINT(A57,$B$2:$B$46,$A$2:$A$46,0.95,1,1) -> 89.125806
A58: 40600 | C58: =_xlfn.FORECAST.ETS(A58,$B$2:$B$46,$A$2:$A$46,1,1) -> 45.310168 | D58: =C58-_xlfn.FORECAST.ETS.CONFINT(A58,$B$2:$B$46,$A$2:$A$46,0.95,1,1) -> 20.897702 | E58: =C58+_xlfn.FORECAST.ETS.CONFINT(A58,$B$2:$B$46,$A$2:$A$46,0.95,1,1) -> 69.722634
... A60: 40602 | C60: =_xlfn.FORECAST.ETS(A60,$B$2:$B$46,$A$2:$A$46,1,1) -> 55.633597 | D60: =C60-_xlfn.FORECAST.ETS.CONFINT(A60,$B$2:$B$46,$A$2:$A$46,0.95,1,1) -> 30.831393 | E60: =C60+_xlfn.FORECAST.ETS.CONFINT(A60,$B$2:$B$46,$A$2:$A$46,0.95,1,1) -> 80.435801

Sheet Sheet16
A1: Date | B1: Wind_Speed | C1: Forecast(Wind_Speed) | D1: Lower Confidence Bound(Wind_Speed) | E1: Upper Confidence Bound(Wind_Speed)
A2: 40544 | B2: 0.16044583
A3: 40545 | B3: 0.24853913
A4: 40546 | B4: 0.24830909
A5: 40547 | B5: 0.16029565
A6: 40548 | B6: 0.1869
A7: 40549 | B7: 0.089565217
A8: 40550 | B8: 0.16872609
A9: 40551 | B9: 0.26680417
A10: 40552 | B10: 0.36195
A11: 40553 | B11: 0.22326667
A12: 40554 | B12: 0.12213182
A13: 40555 | B13: 0.30462727
... A45: 40587 | B45: 0.26088261
A46: 40588 | B46: 0.300375 | C46: 0.300375 | D46: 0.300375 | E46: 0.300375
A47: 40589 | C47: =_xlfn.FORECAST.ETS(A47,$B$2:$B$46,$A$2:$A$46,1,1) -> 0.19820041 | D47: =C47-_xlfn.FORECAST.ETS.CONFINT(A47,$B$2:$B$46,$A$2:$A$46,0.95,1,1) -> 0.035701401 | E47: =C47+_xlfn.FORECAST.ETS.CONFINT(A47,$B$2:$B$46,$A$2:$A$46,0.95,1,1) -> 0.36069942
A48: 40590 | C48: =_xlfn.FORECAST.ETS(A48,$B$2:$B$46,$A$2:$A$46,1,1) -> 0.19822275 | D48: =C48-_xlfn.FORECAST.ETS.CONFINT(A48,$B$2:$B$46,$A$2:$A$46,0.95,1,1) -> 0.034897019 | E48: =C48+_xlfn.FORECAST.ETS.CONFINT(A48,$B$2:$B$46,$A$2:$A$46,0.95,1,1) -> 0.36154849
A49: 40591 | C49: =_xlfn.FORECAST.ETS(A49,$B$2:$B$46,$A$2:$A$46,1,1) -> 0.19824509 | D49: =C49-_xlfn.FORECAST.ETS.CONFINT(A49,$B$2:$B$46,$A$2:$A$46,0.95,1,1) -> 0.034080473 | E49: =C49+_xlfn.FORECAST.ETS.CONFINT(A49,$B$2:$B$46,$A$2:$A$46,0.95,1,1) -> 0.36240972
A50: 40592 | C50: =_xlfn.FORECAST.ETS(A50,$B$2:$B$46,$A$2:$A$46,1,1) -> 0.19826744 | D50: =C50-_xlfn.FORECAST.ETS.CONFINT(A50,$B$2:$B$46,$A$2:$A$46,0.95,1,1) -> 0.033251789 | E50: =C50+_xlfn.FORECAST.ETS.CONFINT(A50,$B$2:$B$46,$A$2:$A$46,0.95,1,1) -> 0.36328308
A51: 40593 | C51: =_xlfn.FORECAST.ETS(A51,$B$2:$B$46,$A$2:$A$46,1,1) -> 0.19828978 | D51: =C51-_xlfn.FORECAST.ETS.CONFINT(A51,$B$2:$B$46,$A$2:$A$46,0.95,1,1) -> 0.032410995 | E51: =C51+_xlfn.FORECAST.ETS.CONFINT(A51,$B$2:$B$46,$A$2:$A$46,0.95,1,1) -> 0.36416856
A52: 40594 | C52: =_xlfn.FORECAST.ETS(A52,$B$2:$B$46,$A$2:$A$46,1,1) -> 0.19831212 | D52: =C52-_xlfn.FORECAST.ETS.CONFINT(A52,$B$2:$B$46,$A$2:$A$46,0.95,1,1) -> 0.03155812 | E52: =C52+_xlfn.FORECAST.ETS.CONFINT(A52,$B$2:$B$46,$A$2:$A$46,0.95,1,1) -> 0.36506611
A53: 40595 | C53: =_xlfn.FORECAST.ETS(A53,$B$2:$B$46,$A$2:$A$46,1,1) -> 0.19833446 | D53: =C53-_xlfn.FORECAST.ETS.CONFINT(A53,$B$2:$B$46,$A$2:$A$46,0.95,1,1) -> 0.030693197 | E53: =C53+_xlfn.FORECAST.ETS.CONFINT(A53,$B$2:$B$46,$A$2:$A$46,0.95,1,1) -> 0.36597572
A54: 40596 | C54: =_xlfn.FORECAST.ETS(A54,$B$2:$B$46,$A$2:$A$46,1,1) -> 0.1983568 | D54: =C54-_xlfn.FORECAST.ETS.CONFINT(A54,$B$2:$B$46,$A$2:$A$46,0.95,1,1) -> 0.029816258 | E54: =C54+_xlfn.FORECAST.ETS.CONFINT(A54,$B$2:$B$46,$A$2:$A$46,0.95,1,1) -> 0.36689734
A55: 40597 | C55: =_xlfn.FORECAST.ETS(A55,$B$2:$B$46,$A$2:$A$46,1,1) -> 0.19837914 | D55: =C55-_xlfn.FORECAST.ETS.CONFINT(A55,$B$2:$B$46,$A$2:$A$46,0.95,1,1) -> 0.028927339 | E55: =C55+_xlfn.FORECAST.ETS.CONFINT(A55,$B$2:$B$46,$A$2:$A$46,0.95,1,1) -> 0.36783094
A56: 40598 | C56: =_xlfn.FORECAST.ETS(A56,$B$2:$B$46,$A$2:$A$46,1,1) -> 0.19840148 | D56: =C56-_xlfn.FORECAST.ETS.CONFINT(A56,$B$2:$B$46,$A$2:$A$46,0.95,1,1) -> 0.028026478 | E56: =C56+_xlfn.FORECAST.ETS.CONFINT(A56,$B$2:$B$46,$A$2:$A$46,0.95,1,1) -> 0.36877648
A57: 40599 | C57: =_xlfn.FORECAST.ETS(A57,$B$2:$B$46,$A$2:$A$46,1,1) -> 0.19842382 | D57: =C57-_xlfn.FORECAST.ETS.CONFINT(A57,$B$2:$B$46,$A$2:$A$46,0.95,1,1) -> 0.027113712 | E57: =C57+_xlfn.FORECAST.ETS.CONFINT(A57,$B$2:$B$46,$A$2:$A$46,0.95,1,1) -> 0.36973393
A58: 40600 | C58: =_xlfn.FORECAST.ETS(A58,$B$2:$B$46,$A$2:$A$46,1,1) -> 0.19844616 | D58: =C58-_xlfn.FORECAST.ETS.CONFINT(A58,$B$2:$B$46,$A$2:$A$46,0.95,1,1) -> 0.026189084 | E58: =C58+_xlfn.FORECAST.ETS.CONFINT(A58,$B$2:$B$46,$A$2:$A$46,0.95,1,1) -> 0.37070324

Sheet Sheet17
A1: Date | B1: Humidity | C1: Forecast(Humidity) | D1: Lower Confidence Bound(Humidity) | E1: Upper Confidence Bound(Humidity)
A2: 40544 | B2: 0.80583333
A3: 40545 | B3: 0.69608696
A4: 40546 | B4: 0.43727273
A5: 40547 | B5: 0.59043478
A6: 40548 | B6: 0.43695652
A7: 40549 | B7: 0.51826087
A8: 40550 | B8: 0.49869565
A9: 40551 | B9: 0.53583333
A10: 40552 | B10: 0.43416667
A11: 40553 | B11: 0.48291667
A12: 40554 | B12: 0.68636364
A13: 40555 | B13: 0.59954545
... A45: 40587 | B45: 0.4573913
A46: 40588 | B46: 0.4475 | C46: 0.4475 | D46: 0.4475 | E46: 0.4475
A47: 40589 | C47: =_xlfn.FORECAST.ETS(A47,$B$2:$B$46,$A$2:$A$46,1,1) -> 0.58188016 | D47: =C47-_xlfn.FORECAST.ETS.CONFINT(A47,$B$2:$B$46,$A$2:$A$46,0.95,1,1) -> 0.32378365 | E47: =C47+_xlfn.FORECAST.ETS.CONFINT(A47,$B$2:$B$46,$A$2:$A$46,0.95,1,1) -> 0.83997667
A48: 40590 | C48: =_xlfn.FORECAST.ETS(A48,$B$2:$B$46,$A$2:$A$46,1,1) -> 0.53477901 | D48: =C48-_xlfn.FORECAST.ETS.CONFINT(A48,$B$2:$B$46,$A$2:$A$46,0.95,1,1) -> 0.26861356 | E48: =C48+_xlfn.FORECAST.ETS.CONFINT(A48,$B$2:$B$46,$A$2:$A$46,0.95,1,1) -> 0.80094447
A49: 40591 | C49: =_xlfn.FORECAST.ETS(A49,$B$2:$B$46,$A$2:$A$46,1,1) -> 0.50218141 | D49: =C49-_xlfn.FORECAST.ETS.CONFINT(A49,$B$2:$B$46,$A$2:$A$46,0.95,1,1) -> 0.22812315 | E49: =C49+_xlfn.FORECAST.ETS.CONFINT(A49,$B$2:$B$46,$A$2:$A$46,0.95,1,1) -> 0.77623968
A50: 40592 | C50: =_xlfn.FORECAST.ETS(A50,$B$2:$B$46,$A$2:$A$46,1,1) -> 0.41238128 | D50: =C50-_xlfn.FORECAST.ETS.CONFINT(A50,$B$2:$B$46,$A$2:$A$46,0.95,1,1) -> 0.1305913 | E50: =C50+_xlfn.FORECAST.ETS.CONFINT(A50,$B$2:$B$46,$A$2:$A$46,0.95,1,1) -> 0.69417125
A51: 40593 | C51: =_xlfn.FORECAST.ETS(A51,$B$2:$B$46,$A$2:$A$46,1,1) -> 0.39451571 | D51: =C51-_xlfn.FORECAST.ETS.CONFINT(A51,$B$2:$B$46,$A$2:$A$46,0.95,1,1) -> 0.10514199 | E51: =C51+_xlfn.FORECAST.ETS.CONFINT(A51,$B$2:$B$46,$A$2:$A$46,0.95,1,1) -> 0.68388944
A52: 40594 | C52: =_xlfn.FORECAST.ETS(A52,$B$2:$B$46,$A$2:$A$46,1,1) -> 0.42653953 | D52: =C52-_xlfn.FORECAST.ETS.CONFINT(A52,$B$2:$B$46,$A$2:$A$46,0.95,1,1) -> 0.12971845 | E52: =C52+_xlfn.FORECAST.ETS.CONFINT(A52,$B$2:$B$46,$A$2:$A$46,0.95,1,1) -> 0.72336062
A53: 40595 | C53: =_xlfn.FORECAST.ETS(A53,$B$2:$B$46,$A$2:$A$46,1,1) -> 0.45203949 | D53: =C53-_xlfn.FORECAST.ETS.CONFINT(A53,$B$2:$B$46,$A$2:$A$46,0.95,1,1) -> 0.1478972 | E53: =C53+_xlfn.FORECAST.ETS.CONFINT(A53,$B$2:$B$46,$A$2:$A$46,0.95,1,1) -> 0.75618178
A54: 40596 | C54: =_xlfn.FORECAST.ETS(A54,$B$2:$B$46,$A$2:$A$46,1,1) -> 0.56317257 | D54: =C54-_xlfn.FORECAST.ETS.CONFINT(A54,$B$2:$B$46,$A$2:$A$46,0.95,1,1) -> 0.25182612 | E54: =C54+_xlfn.FORECAST.ETS.CONFINT(A54,$B$2:$B$46,$A$2:$A$46,0.95,1,1) -> 0.87451902
A55: 40597 | C55: =_xlfn.FORECAST.ETS(A55,$B$2:$B$46,$A$2:$A$46,1,1) -> 0.57379474 | D55: =C55-_xlfn.FORECAST.ETS.CONFINT(A55,$B$2:$B$46,$A$2:$A$46,0.95,1,1) -> 0.25535301 | E55: =C55+_xlfn.FORECAST.ETS.CONFINT(A55,$B$2:$B$46,$A$2:$A$46,0.95,1,1) -> 0.89223646
A56: 40598 | C56: =_xlfn.FORECAST.ETS(A56,$B$2:$B$46,$A$2:$A$46,1,1) -> 0.57988737 | D56: =C56-_xlfn.FORECAST.ETS.CONFINT(A56,$B$2:$B$46,$A$2:$A$46,0.95,1,1) -> 0.25439861 | E56: =C56+_xlfn.FORECAST.ETS.CONFINT(A56,$B$2:$B$46,$A$2:$A$46,0.95,1,1) -> 0.90537613
A57: 40599 | C57: =_xlfn.FORECAST.ETS(A57,$B$2:$B$46,$A$2:$A$46,1,1) -> 0.53278622 | D57: =C57-_xlfn.FORECAST.ETS.CONFINT(A57,$B$2:$B$46,$A$2:$A$46,0.95,1,1) -> 0.2003998 | E57: =C57+_xlfn.FORECAST.ETS.CONFINT(A57,$B$2:$B$46,$A$2:$A$46,0.95,1,1) -> 0.86517264
A58: 40600 | C58: =_xlfn.FORECAST.ETS(A58,$B$2:$B$46,$A$2:$A$46,1,1) -> 0.50018862 | D58: =C58-_xlfn.FORECAST.ETS.CONFINT(A58,$B$2:$B$46,$A$2:$A$46,0.95,1,1) -> 0.16099344 | E58: =C58+_xlfn.FORECAST.ETS.CONFINT(A58,$B$2:$B$46,$A$2:$A$46,0.95,1,1) -> 0.8393838
... A64: 40606 | C64: =_xlfn.FORECAST.ETS(A64,$B$2:$B$46,$A$2:$A$46,1,1) -> 0.57180194 | D64: =C64-_xlfn.FORECAST.ETS.CONFINT(A64,$B$2:$B$46,$A$2:$A$46,0.95,1,1) -> 0.19334682 | E64: =C64+_xlfn.FORECAST.ETS.CONFINT(A64,$B$2:$B$46,$A$2:$A$46,0.95,1,1) -> 0.95025707

Sheet Sheet20
A1: Date | B1: Temperature | C1: Forecast(Temperature) | D1: Lower Confidence Bound(Temperature) | E1: Upper Confidence Bound(Temperature)
A2: 40544 | B2: 0.34416667
A3: 40545 | B3: 0.36347826
A4: 40546 | B4: 0.19636364
A5: 40547 | B5: 0.2
A6: 40548 | B6: 0.22695652
A7: 40549 | B7: 0.20434783
A8: 40550 | B8: 0.19652174
A9: 40551 | B9: 0.165
A10: 40552 | B10: 0.13833333
A11: 40553 | B11: 0.15083333
A12: 40554 | B12: 0.16909091
A13: 40555 | B13: 0.17272727
... A45: 40587 | B45: 0.31652174
A46: 40588 | B46: 0.3475 | C46: 0.3475 | D46: 0.3475 | E46: 0.3475
A47: 40589 | C47: =_xlfn.FORECAST.ETS(A47,$B$2:$B$46,$A$2:$A$46,1,1) -> 0.34429038 | D47: =C47-_xlfn.FORECAST.ETS.CONFINT(A47,$B$2:$B$46,$A$2:$A$46,0.95,1,1) -> 0.21584718 | E47: =C47+_xlfn.FORECAST.ETS.CONFINT(A47,$B$2:$B$46,$A$2:$A$46,0.95,1,1) -> 0.47273359
A48: 40590 | C48: =_xlfn.FORECAST.ETS(A48,$B$2:$B$46,$A$2:$A$46,1,1) -> 0.29030044 | D48: =C48-_xlfn.FORECAST.ETS.CONFINT(A48,$B$2:$B$46,$A$2:$A$46,0.95,1,1) -> 0.10874512 | E48: =C48+_xlfn.FORECAST.ETS.CONFINT(A48,$B$2:$B$46,$A$2:$A$46,0.95,1,1) -> 0.47185575
A49: 40591 | C49: =_xlfn.FORECAST.ETS(A49,$B$2:$B$46,$A$2:$A$46,1,1) -> 0.33275898 | D49: =C49-_xlfn.FORECAST.ETS.CONFINT(A49,$B$2:$B$46,$A$2:$A$46,0.95,1,1) -> 0.11036296 | E49: =C49+_xlfn.FORECAST.ETS.CONFINT(A49,$B$2:$B$46,$A$2:$A$46,0.95,1,1) -> 0.555155
A50: 40592 | C50: =_xlfn.FORECAST.ETS(A50,$B$2:$B$46,$A$2:$A$46,1,1) -> 0.4088408 | D50: =C50-_xlfn.FORECAST.ETS.CONFINT(A50,$B$2:$B$46,$A$2:$A$46,0.95,1,1) -> 0.15195433 | E50: =C50+_xlfn.FORECAST.ETS.CONFINT(A50,$B$2:$B$46,$A$2:$A$46,0.95,1,1) -> 0.66572727
A51: 40593 | C51: =_xlfn.FORECAST.ETS(A51,$B$2:$B$46,$A$2:$A$46,1,1) -> 0.3779125 | D51: =C51-_xlfn.FORECAST.ETS.CONFINT(A51,$B$2:$B$46,$A$2:$A$46,0.95,1,1) -> 0.090589739 | E51: =C51+_xlfn.FORECAST.ETS.CONFINT(A51,$B$2:$B$46,$A$2:$A$46,0.95,1,1) -> 0.66523526
A52: 40594 | C52: =_xlfn.FORECAST.ETS(A52,$B$2:$B$46,$A$2:$A$46,1,1) -> 0.28974703 | D52: =C52-_xlfn.FORECAST.ETS.CONFINT(A52,$B$2:$B$46,$A$2:$A$46,0.95,1,1) -> -0.025135742 | E52: =C52+_xlfn.FORECAST.ETS.CONFINT(A52,$B$2:$B$46,$A$2:$A$46,0.95,1,1) -> 0.6046298
A53: 40595 | C53: =_xlfn.FORECAST.ETS(A53,$B$2:$B$46,$A$2:$A$46,1,1) -> 0.24245156 | D53: =C53-_xlfn.FORECAST.ETS.CONFINT(A53,$B$2:$B$46,$A$2:$A$46,0.95,1,1) -> -0.097814597 | E53: =C53+_xlfn.FORECAST.ETS.CONFINT(A53,$B$2:$B$46,$A$2:$A$46,0.95,1,1) -> 0.58271772
A54: 40596 | C54: =_xlfn.FORECAST.ETS(A54,$B$2:$B$46,$A$2:$A$46,1,1) -> 0.24675747 | D54: =C54-_xlfn.FORECAST.ETS.CONFINT(A54,$B$2:$B$46,$A$2:$A$46,0.95,1,1) -> -0.11717124 | E54: =C54+_xlfn.FORECAST.ETS.CONFINT(A54,$B$2:$B$46,$A$2:$A$46,0.95,1,1) -> 0.61068617
A55: 40597 | C55: =_xlfn.FORECAST.ETS(A55,$B$2:$B$46,$A$2:$A$46,1,1) -> 0.23419194 | D55: =C55-_xlfn.FORECAST.ETS.CONFINT(A55,$B$2:$B$46,$A$2:$A$46,0.95,1,1) -> -0.15199497 | E55: =C55+_xlfn.FORECAST.ETS.CONFINT(A55,$B$2:$B$46,$A$2:$A$46,0.95,1,1) -> 0.62037885
A56: 40598 | C56: =_xlfn.FORECAST.ETS(A56,$B$2:$B$46,$A$2:$A$46,1,1) -> 0.30327177 | D56: =C56-_xlfn.FORECAST.ETS.CONFINT(A56,$B$2:$B$46,$A$2:$A$46,0.95,1,1) -> -0.10399934 | E56: =C56+_xlfn.FORECAST.ETS.CONFINT(A56,$B$2:$B$46,$A$2:$A$46,0.95,1,1) -> 0.71054289
A57: 40599 | C57: =_xlfn.FORECAST.ETS(A57,$B$2:$B$46,$A$2:$A$46,1,1) -> 0.31195174 | D57: =C57-_xlfn.FORECAST.ETS.CONFINT(A57,$B$2:$B$46,$A$2:$A$46,0.95,1,1) -> -0.11540342 | E57: =C57+_xlfn.FORECAST.ETS.CONFINT(A57,$B$2:$B$46,$A$2:$A$46,0.95,1,1) -> 0.7393069
A58: 40600 | C58: =_xlfn.FORECAST.ETS(A58,$B$2:$B$46,$A$2:$A$46,1,1) -> 0.30403239 | D58: =C58-_xlfn.FORECAST.ETS.CONFINT(A58,$B$2:$B$46,$A$2:$A$46,0.95,1,1) -> -0.14254166 | E58: =C58+_xlfn.FORECAST.ETS.CONFINT(A58,$B$2:$B$46,$A$2:$A$46,0.95,1,1) -> 0.75060644
... A76: 40618 | C76: =_xlfn.FORECAST.ETS(A76,$B$2:$B$46,$A$2:$A$46,1,1) -> 0.38164493 | D76: =C76-_xlfn.FORECAST.ETS.CONFINT(A76,$B$2:$B$46,$A$2:$A$46,0.95,1,1) -> -0.33075713 | E76: =C76+_xlfn.FORECAST.ETS.CONFINT(A76,$B$2:$B$46,$A$2:$A$46,0.95,1,1) -> 1.094047

Sheet Forecast Sheet
B3: Bike Rental Demand Forecast Sheet
A6: Total_Rentals | B6: Casual_Rentals | C6: Registered_Rentals | D6: Temperature | E6: Humidity | F6: Wind_Speed
A7: 41.041667 | B7: 13.791667 | C7: 27.25 | D7: 0.34416667 | E7: 0.80583333 | F7: 0.16044583
A8: 34.826087 | B8: 5.6956522 | C8: 29.130435 | D8: 0.36347826 | E8: 0.69608696 | F8: 0.24853913
A9: 61.318182 | B9: 5.4545455 | C9: 55.863636 | D9: 0.19636364 | E9: 0.43727273 | F9: 0.24830909
A10: 67.913043 | B10: 4.6956522 | C10: 63.217391 | D10: 0.2 | E10: 0.59043478 | F10: 0.16029565
A11: 69.565217 | B11: 3.5652174 | C11: 66 | D11: 0.22695652 | E11: 0.43695652 | F11: 0.1869
A12: 69.826087 | B12: 3.826087 | C12: 66 | D12: 0.20434783 | E12: 0.51826087 | F12: 0.089565217
A13: 65.652174 | B13: 6.4347826 | C13: 59.217391 | D13: 0.19652174 | E13: 0.49869565 | F13: 0.16872609
A14: 39.958333 | B14: 2.8333333 | C14: 37.125 | D14: 0.165 | E14: 0.53583333 | F14: 0.26680417
A15: 34.25 | B15: 2.25 | C15: 32 | D15: 0.13833333 | E15: 0.43416667 | F15: 0.36195
A16: 55.041667 | B16: 1.7083333 | C16: 53.333333 | D16: 0.15083333 | E16: 0.48291667 | F16: 0.22326667
A17: 57.409091 | B17: 1.9545455 | C17: 55.454545 | D17: 0.16909091 | E17: 0.68636364 | F17: 0.12213182
A18: 52.818182 | B18: 1.1363636 | C18: 51.681818 | D18: 0.17272727 | E18: 0.59954545 | F18: 0.30462727
... A51: 18.875 | B51: 1 | C51: 17.875 | D51: 0.3475 | E51: 0.4475 | F51: 0.300375

Sheet Final Forecast Chart
D2: Bike Rental Demand Forecast chart

Sheet rough work
A1: Record_Id | B1: Date | C1: Season_Code | D1: Year | E1: Month | F1: Hour | G1: Holiday | H1: Day_Code | I1: Day_Type | J1: Weather_Code | K1: Weather_Type | L1: Temperature | M1: Assumed_Temperature | N1: Humidity | O1: Wind_Speed | P1: Casual_Rentals | Q1: Registered_Rentals | R1: Total_Rentals | S1: Weather_Description
A2: 1 | B2: 40544 | C2: 1 | D2: 0 | E2: 1 | F2: 0 | G2: FALSE | H2: 6 | I2: Saturday | J2: 1 | K2: Clear | L2: 0.24 | M2: 0.2879 | N2: 0.81 | O2: 0 | P2: 3 | Q2: 13 | R2: =SUM(Append18[[#This Row],[Casual_Rentals]],Append18[[#This Row],[Registered_Rentals]]) -> 16 | T2: Day_code | U2: day | V2: =IF(M2="",M1,M2) -> 0.2879 | W2: =IF(C2=1,"winter",("invalid")) -> winter
A3: 2 | B3: 40544 | C3: 1 | D3: 0 | E3: 1 | F3: 1 | G3: FALSE | H3: 6 | I3: Saturday | J3: 1 | K3: Clear | L3: 0.22 | M3: 0.2727 | N3: 0.8 | O3: 0 | P3: 8 | Q3: 32 | R3: =SUM(Append18[[#This Row],[Casual_Rentals]],Append18[[#This Row],[Registered_Rentals]]) -> 40 | T3: 0 | U3: Sunday | V3: =IF(M3="",M2,M3) -> 0.2727 | W3: =IF(C3=1,"winter",("invalid")) -> winter
A4: 3 | B4: 40544 | C4: 1 | D4: 0 | E4: 1 | F4: 2 | G4: FALSE | H4: 6 | I4: Saturday | J4: 1 | K4: Clear | L4: 0.22 | M4: 0.2727 | N4: 0.8 | O4: 0 | P4: 5 | Q4: 27 | R4: =SUM(Append18[[#This Row],[Casual_Rentals]],Append18[[#This Row],[Registered_Rentals]]) -> 32 | T4: 1 | U4: Monday | V4: =IF(M4="",M3,M4) -> 0.2727 | W4: =IF(C4=1,"winter",("invalid")) -> winter
A5: 4 | B5: 40544 | C5: 1 | D5: 0 | E5: 1 | F5: 3 | G5: FALSE | H5: 6 | I5: Saturday | J5: 1 | K5: Clear | L5: 0.24 | M5: 0.2879 | N5: 0.75 | O5: 0 | P5: 3 | Q5: 10 | R5: =SUM(Append18[[#This Row],[Casual_Rentals]],Append18[[#This Row],[Registered_Rentals]]) -> 13 | T5: 2 | U5: Tuesday | V5: =IF(M5="",M4,M5) -> 0.2879 | W5: =IF(C5=1,"winter",("invalid")) -> winter
A6: 5 | B6: 40544 | C6: 1 | D6: 0 | E6: 1 | F6: 4 | G6: FALSE | H6: 6 | I6: Saturday | J6: 1 | K6: Clear | L6: 0.24 | M6: 0.2879 | N6: 0.75 | O6: 0 | P6: 0 | Q6: 1 | R6: =SUM(Append18[[#This Row],[Casual_Rentals]],Append18[[#This Row],[Registered_Rentals]]) -> 1 | T6: 3 | U6: Wednesday | V6: =IF(M6="",M5,M6) -> 0.2879 | W6: =IF(C6=1,"winter",("invalid")) -> winter
A7: 6 | B7: 40544 | C7: 1 | D7: 0 | E7: 1 | F7: 5 | G7: FALSE | H7: 6 | I7: Saturday | J7: 2 | K7: Cloudy | L7: 0.24 | M7: 0.2576 | N7: 0.75 | O7: 0.0896 | P7: 0 | Q7: 1 | R7: =SUM(Append18[[#This Row],[Casual_Rentals]],Append18[[#This Row],[Registered_Rentals]]) -> 1 | T7: 4 | U7: Thursday | V7: =IF(M7="",M6,M7) -> 0.2576 | W7: =IF(C7=1,"winter",("invalid")) -> winter
A8: 7 | B8: 40544 | C8: 1 | D8: 0 | E8: 1 | F8: 6 | G8: FALSE | H8: 6 | I8: Saturday | J8: 1 | K8: Clear | L8: 0.22 | M8: 0.2727 | N8: 0.8 | O8: 0 | P8: 2 | Q8: 0 | R8: =SUM(Append18[[#This Row],[Casual_Rentals]],Append18[[#This Row],[Registered_Rentals]]) -> 2 | T8: 5 | U8: Friday | V8: =IF(M8="",M7,M8) -> 0.2727 | W8: =IF(C8=1,"winter",("invalid")) -> winter
A9: 8 | B9: 40544 | C9: 1 | D9: 0 | E9: 1 | F9: 7 | G9: FALSE | H9: 6 | I9: Saturday | J9: 1 | K9: Clear | L9: 0.2 | M9: 0.2576 | N9: 0.86 | O9: 0 | P9: 1 | Q9: 2 | R9: =SUM(Append18[[#This Row],[Casual_Rentals]],Append18[[#This Row],[Registered_Rentals]]) -> 3 | T9: 6 | U9: Saturday | V9: =IF(M9="",M8,M9) -> 0.2576 | W9: =IF(C9=1,"winter",("invalid")) -> winter
A10: 9 | B10: 40544 | C10: 1 | D10: 0 | E10: 1 | F10: 8 | G10: FALSE | H10: 6 | I10: Saturday | J10: 1 | K10: Clear | L10: 0.24 | M10: 0.2576 | N10: 0.75 | O10: 0 | P10: 1 | Q10: 7 | R10: =SUM(Append18[[#This Row],[Casual_Rentals]],Append18[[#This Row],[Registered_Rentals]]) -> 8 | V10: =IF(M10="",M9,M10) -> 0.2576 | W10: =IF(C10=1,"winter",("invalid")) -> winter
A11: 10 | B11: 40544 | C11: 1 | D11: 0 | E11: 1 | F11: 9 | G11: FALSE | H11: 6 | I11: Saturday | J11: 1 | K11: Clear | L11: 0.32 | M11: 0.3485 | N11: 0.76 | O11: 0 | P11: 8 | Q11: 6 | R11: =SUM(Append18[[#This Row],[Casual_Rentals]],Append18[[#This Row],[Registered_Rentals]]) -> 14 | T11: =IF(H2=0,"SUNDAY",IF(H2=1,"Monday",IF(H2=2,"Tuesday",IF(H2=3,"Wednesday",IF(H2=4,"Thursday",IF(H2=5,"Friday",IF(H2=6,"Saturday",("Invalid")))))))) -> Saturday | U11: =IF(E2=1,"January",IF(E2=2,"February",("invalid"))) -> January | V11: =IF(M11="",M10,M11) -> 0.3485 | W11: =IF(C11=1,"winter",("invalid")) -> winter
A12: 11 | B12: 40544 | C12: 1 | D12: 0 | E12: 1 | F12: 10 | G12: FALSE | H12: 6 | I12: Saturday | J12: 1 | K12: Clear | L12: 0.38 | M12: 0.3939 | N12: 0.76 | O12: 0.2537 | P12: 12 | Q12: 24 | R12: =SUM(Append18[[#This Row],[Casual_Rentals]],Append18[[#This Row],[Registered_Rentals]]) -> 36 | U12: =IF(E3=1,"January",IF(E3=2,"February",("invalid"))) -> January | V12: =IF(M12="",M11,M12) -> 0.3939 | W12: =IF(C12=1,"winter",("invalid")) -> winter
A13: 12 | B13: 40544 | C13: 1 | D13: 0 | E13: 1 | F13: 11 | G13: FALSE | H13: 6 | I13: Saturday | J13: 1 | K13: Clear | L13: 0.36 | M13: 0.3333 | N13: 0.81 | O13: 0.2836 | P13: 26 | Q13: 30 | R13: =SUM(Append18[[#This Row],[Casual_Rentals]],Append18[[#This Row],[Registered_Rentals]]) -> 56 | T13: =SUM(P2:P1001) -> 4921 | U13: =IF(E4=1,"January",IF(E4=2,"February",("invalid"))) -> January | V13: =IF(M13="",M12,M13) -> 0.3333 | W13: =IF(C13=1,"winter",("invalid")) -> winter
A14: 13 | B14: 40544 | C14: 1 | D14: 0 | E14: 1 | F14: 12 | G14: FALSE | H14: 6 | I14: Saturday | J14: 1 | K14: Clear | L14: 0.42 | M14: 0.4242 | N14: 0.77 | O14: 0.2836 | P14: 29 | Q14: 55 | R14: =SUM(Append18[[#This Row],[Casual_Rentals]],Append18[[#This Row],[Registered_Rentals]]) -> 84 | U14: =IF(E5=1,"January",IF(E5=2,"February",("invalid"))) -> January | V14: =IF(M14="",M13,M14) -> 0.4242 | W14: =IF(C14=1,"winter",("invalid")) -> winter
A15: 14 | B15: 40544 | C15: 1 | D15: 0 | E15: 1 | F15: 13 | G15: FALSE | H15: 6 | I15: Saturday | J15: 2 | K15: Cloudy | L15: 0.46 | M15: 0.4545 | N15: 0.72 | O15: 0.2985 | P15: 47 | Q15: 47 | R15: =SUM(Append18[[#This Row],[Casual_Rentals]],Append18[[#This Row],[Registered_Rentals]]) -> 94 | U15: =IF(E6=1,"January",IF(E6=2,"February",("invalid"))) -> January | V15: =IF(M15="",M14,M15) -> 0.4545 | W15: =IF(C15=1,"winter",("invalid")) -> winter
A16: 15 | B16: 40544 | C16: 1 | D16: 0 | E16: 1 | F16: 14 | G16: FALSE | H16: 6 | I16: Saturday | J16: 2 | K16: Cloudy | L16: 0.46 | M16: 0.4545 | N16: 0.72 | O16: 0.2836 | P16: 35 | Q16: 71 | R16: =SUM(Append18[[#This Row],[Casual_Rentals]],Append18[[#This Row],[Registered_Rentals]]) -> 106 | T16: =IF(K2=1,"Clear",IF(K2=2,"Cloudy",IF(K2=3,"Light Rain",IF(K2=4,"Heavy Rain",("invalid"))))) -> invalid | U16: =IF(E7=1,"January",IF(E7=2,"February",("invalid"))) -> January | V16: =IF(M16="",M15,M16) -> 0.4545 | W16: =IF(C16=1,"winter",("invalid")) -> winter
A17: 16 | B17: 40544 | C17: 1 | D17: 0 | E17: 1 | F17: 15 | G17: FALSE | H17: 6 | I17: Saturday | J17: 2 | K17: Cloudy | L17: 0.44 | M17: 0.4394 | N17: 0.77 | O17: 0.2985 | P17: 40 | Q17: 70 | R17: =SUM(Append18[[#This Row],[Casual_Rentals]],Append18[[#This Row],[Registered_Rentals]]) -> 110 | T17: =IF(K3=1,"Clear",IF(K3=2,"Cloudy",IF(K3=3,"Light Rain",IF(K3=4,"Heavy Rain",("invalid"))))) -> invalid | U17: =IF(E8=1,"January",IF(E8=2,"February",("invalid"))) -> January | V17: =IF(M17="",M16,M17) -> 0.4394 | W17: =IF(C17=1,"winter",("invalid")) -> winter
A18: 17 | B18: 40544 | C18: 1 | D18: 0 | E18: 1 | F18: 16 | G18: FALSE | H18: 6 | I18: Saturday | J18: 2 | K18: Cloudy | L18: 0.42 | M18: 0.4242 | N18: 0.82 | O18: 0.2985 | P18: 41 | Q18: 52 | R18: =SUM(Append18[[#This Row],[Casual_Rentals]],Append18[[#This Row],[Registered_Rentals]]) -> 93 | T18: =IF(K4=1,"Clear",IF(K4=2,"Cloudy",IF(K4=3,"Light Rain",IF(K4=4,"Heavy Rain",("invalid"))))) -> invalid | U18: =IF(E9=1,"January",IF(E9=2,"February",("invalid"))) -> January | V18: =IF(M18="",M17,M18) -> 0.4242 | W18: =IF(C18=1,"winter",("invalid")) -> winter
A19: 18 | B19: 40544 | C19: 1 | D19: 0 | E19: 1 | F19: 17 | G19: FALSE | H19: 6 | I19: Saturday | J19: 2 | K19: Cloudy | L19: 0.44 | M19: 0.999 | N19: 0.82 | O19: 0.2836 | P19: 15 | Q19: 52 | R19: =SUM(Append18[[#This Row],[Casual_Rentals]],Append18[[#This Row],[Registered_Rentals]]) -> 67 | T19: =IF(K5=1,"Clear",IF(K5=2,"Cloudy",IF(K5=3,"Light Rain",IF(K5=4,"Heavy Rain",("invalid"))))) -> invalid | U19: =IF(E10=1,"January",IF(E10=2,"February",("invalid"))) -> January | V19: =IF(M19="",M18,M19) -> 0.999 | W19: =IF(C19=1,"winter",("invalid")) -> winter
A20: 19 | B20: 40544 | C20: 1 | D20: 0 | E20: 1 | F20: 18 | G20: FALSE | H20: 6 | I20: Saturday | J20: 3 | K20: Light Rain | L20: 0.42 | M20: 0.4242 | N20: 0.88 | O20: 0.2537 | P20: 9 | Q20: 26 | R20: =SUM(Append18[[#This Row],[Casual_Rentals]],Append18[[#This Row],[Registered_Rentals]]) -> 35 | T20: =IF(K6=1,"Clear",IF(K6=2,"Cloudy",IF(K6=3,"Light Rain",IF(K6=4,"Heavy Rain",("invalid"))))) -> invalid | U20: =IF(E11=1,"January",IF(E11=2,"February",("invalid"))) -> January | V20: =IF(M20="",M19,M20) -> 0.4242 | W20: =IF(C20=1,"winter",("invalid")) -> winter
A21: 20 | B21: 40544 | C21: 1 | D21: 0 | E21: 1 | F21: 19 | G21: FALSE | H21: 6 | I21: Saturday | J21: 3 | K21: Light Rain | L21: 0.42 | M21: 0.4242 | N21: 0.88 | O21: 0.2537 | P21: 6 | Q21: 31 | R21: =SUM(Append18[[#This Row],[Casual_Rentals]],Append18[[#This Row],[Registered_Rentals]]) -> 37 | T21: =IF(K7=1,"Clear",IF(K7=2,"Cloudy",IF(K7=3,"Light Rain",IF(K7=4,"Heavy Rain",("invalid"))))) -> invalid | U21: =IF(E12=1,"January",IF(E12=2,"February",("invalid"))) -> January | V21: =IF(M21="",M20,M21) -> 0.4242 | W21: =IF(C21=1,"winter",("invalid")) -> winter
A22: 21 | B22: 40544 | C22: 1 | D22: 0 | E22: 1 | F22: 20 | G22: FALSE | H22: 6 | I22: Saturday | J22: 2 | K22: Cloudy | L22: 0.4 | M22: 0.4091 | N22: 0.87 | O22: 0.2537 | P22: 11 | Q22: 25 | R22: =SUM(Append18[[#This Row],[Casual_Rentals]],Append18[[#This Row],[Registered_Rentals]]) -> 36 | T22: =IF(K8=1,"Clear",IF(K8=2,"Cloudy",IF(K8=3,"Light Rain",IF(K8=4,"Heavy Rain",("invalid"))))) -> invalid | U22: =IF(E13=1,"January",IF(E13=2,"February",("invalid"))) -> January | V22: =IF(M22="",M21,M22) -> 0.4091 | W22: =IF(C22=1,"winter",("invalid")) -> winter
A23: 22 | B23: 40544 | C23: 1 | D23: 0 | E23: 1 | F23: 21 | G23: FALSE | H23: 6 | I23: Saturday | J23: 2 | K23: Cloudy | L23: 0.4 | M23: 0.4091 | N23: 0.87 | O23: 0.194 | P23: 3 | Q23: 31 | R23: =SUM(Append18[[#This Row],[Casual_Rentals]],Append18[[#This Row],[Registered_Rentals]]) -> 34 | T23: =IF(K9=1,"Clear",IF(K9=2,"Cloudy",IF(K9=3,"Light Rain",IF(K9=4,"Heavy Rain",("invalid"))))) -> invalid | U23: =IF(E14=1,"January",IF(E14=2,"February",("invalid"))) -> January | V23: =IF(M23="",M22,M23) -> 0.4091 | W23: =IF(C23=1,"winter",("invalid")) -> winter
A24: 23 | B24: 40544 | C24: 1 | D24: 0 | E24: 1 | F24: 22 | G24: FALSE | H24: 6 | I24: Saturday | J24: 2 | K24: Cloudy | L24: 0.4 | M24: 0.4091 | N24: 0.94 | O24: 0.2239 | P24: 11 | Q24: 17 | R24: =SUM(Append18[[#This Row],[Casual_Rentals]],Append18[[#This Row],[Registered_Rentals]]) -> 28 | T24: =IF(K10=1,"Clear",IF(K10=2,"Cloudy",IF(K10=3,"Light Rain",IF(K10=4,"Heavy Rain",("invalid"))))) -> invalid | U24: =IF(E15=1,"January",IF(E15=2,"February",("invalid"))) -> January | V24: =IF(M24="",M23,M24) -> 0.4091 | W24: =IF(C24=1,"winter",("invalid")) -> winter
A25: 24 | B25: 40544 | C25: 1 | D25: 0 | E25: 1 | F25: 23 | G25: FALSE | H25: 6 | I25: Saturday | J25: 2 | K25: Cloudy | L25: 0.46 | M25: 0.4091 | N25: 0.88 | O25: 0.2985 | P25: 15 | Q25: 24 | R25: =SUM(Append18[[#This Row],[Casual_Rentals]],Append18[[#This Row],[Registered_Rentals]]) -> 39 | T25: =IF(K11=1,"Clear",IF(K11=2,"Cloudy",IF(K11=3,"Light Rain",IF(K11=4,"Heavy Rain",("invalid"))))) -> invalid | U25: =IF(E16=1,"January",IF(E16=2,"February",("invalid"))) -> January | V25: =IF(M25="",M24,M25) -> 0.4091 | W25: =IF(C25=1,"winter",("invalid")) -> winter
A26: 25 | B26: 40545 | C26: 1 | D26: 0 | E26: 1 | F26: 0 | G26: FALSE | H26: 0 | I26: SUNDAY | J26: 2 | K26: Cloudy | L26: 0.46 | M26: 0.4545 | N26: 0.88 | O26: 0.2985 | P26: 4 | Q26: 13 | R26: =SUM(Append18[[#This Row],[Casual_Rentals]],Append18[[#This Row],[Registered_Rentals]]) -> 17 | T26: =IF(K12=1,"Clear",IF(K12=2,"Cloudy",IF(K12=3,"Light Rain",IF(K12=4,"Heavy Rain",("invalid"))))) -> invalid | U26: =IF(E17=1,"January",IF(E17=2,"February",("invalid"))) -> January | V26: =IF(M26="",M25,M26) -> 0.4545 | W26: =IF(C26=1,"winter",("invalid")) -> winter
A27: 26 | B27: 40545 | C27: 1 | D27: 0 | E27: 1 | F27: 1 | G27: FALSE | H27: 0 | I27: SUNDAY | J27: 2 | K27: Cloudy | L27: 0.44 | M27: 0.4394 | N27: 0.94 | O27: 0.2537 | P27: 1 | Q27: 16 | R27: =SUM(Append18[[#This Row],[Casual_Rentals]],Append18[[#This Row],[Registered_Rentals]]) -> 17 | T27: =IF(K13=1,"Clear",IF(K13=2,"Cloudy",IF(K13=3,"Light Rain",IF(K13=4,"Heavy Rain",("invalid"))))) -> invalid | U27: =IF(E18=1,"January",IF(E18=2,"February",("invalid"))) -> January | V27: =IF(M27="",M26,M27) -> 0.4394 | W27: =IF(C27=1,"winter",("invalid")) -> winter
... A611: 610 | B611: 40571 | C611: 1 | D611: 0 | E611: 1 | F611: 15 | G611: FALSE | H611: 5 | I611: Friday | J611: 2 | K611: Cloudy | L611: 0.2 | M611: 0.2576 | N611: 0.86 | O611: 0 | P611: 1 | Q611: 40 | R611: =SUM(Append18[[#This Row],[Casual_Rentals]],Append18[[#This Row],[Registered_Rentals]]) -> 41 | T611: =IF(K597=1,"Clear",IF(K597=2,"Cloudy",IF(K597=3,"Light Rain",IF(K597=4,"Heavy Rain",("invalid"))))) -> invalid | U611: =IF(E602=1,"January",IF(E602=2,"February",("invalid"))) -> January | V611: =IF(M611="",M610,M611) -> 0.2576 | W611: =IF(C611=1,"winter",("invalid")) -> winter
A612: 611 | B612: 40571 | C612: 1 | D612: 0 | E612: 1 | F612: 16 | G612: FALSE | H612: 5 | I612: Friday | J612: 1 | K612: Clear | L612: 0.22 | M612: 0.2727 | N612: 0.8 | O612: 0 | P612: 10 | Q612: 70 | R612: 80 | T612: =IF(K598=1,"Clear",IF(K598=2,"Cloudy",IF(K598=3,"Light Rain",IF(K598=4,"Heavy Rain",("invalid"))))) -> invalid | U612: =IF(E603=1,"January",IF(E603=2,"February",("invalid"))) -> January | V612: =IF(M612="",M611,M612) -> 0.2727 | W612: =IF(C612=1,"winter",("invalid")) -> winter
A613: 612 | B613: 40571 | C613: 1 | D613: 0 | E613: 1 | F613: 17 | G613: FALSE | H613: 5 | I613: Friday | J613: 1 | K613: Clear | L613: 0.24 | M613: 0.2424 | N613: 0.75 | O613: 0.1343 | P613: 2 | Q613: 147 | R613: 149 | T613: =IF(K599=1,"Clear",IF(K599=2,"Cloudy",IF(K599=3,"Light Rain",IF(K599=4,"Heavy Rain",("invalid"))))) -> invalid | U613: =IF(E604=1,"January",IF(E604=2,"February",("invalid"))) -> January | V613: =IF(M613="",M612,M613) -> 0.2424 | W613: =IF(C613=1,"winter",("invalid")) -> winter
A614: 613 | B614: 40571 | C614: 1 | D614: 0 | E614: 1 | F614: 18 | G614: FALSE | H614: 5 | I614: Friday | J614: 1 | K614: Clear | L614: 0.24 | M614: 0.2273 | N614: 0.75 | O614: 0.194 | P614: 2 | Q614: 107 | R614: 109 | T614: =IF(K600=1,"Clear",IF(K600=2,"Cloudy",IF(K600=3,"Light Rain",IF(K600=4,"Heavy Rain",("invalid"))))) -> invalid | U614: =IF(E605=1,"January",IF(E605=2,"February",("invalid"))) -> January | V614: =IF(M614="",M613,M614) -> 0.2273 | W614: =IF(C614=1,"winter",("invalid")) -> winter
A615: 614 | B615: 40571 | C615: 1 | D615: 0 | E615: 1 | F615: 19 | G615: FALSE | H615: 5 | I615: Friday | J615: 2 | K615: Cloudy | L615: 0.24 | M615: 0.2424 | N615: 0.75 | O615: 0.1343 | P615: 5 | Q615: 84 | R615: 89 | T615: =IF(K601=1,"Clear",IF(K601=2,"Cloudy",IF(K601=3,"Light Rain",IF(K601=4,"Heavy Rain",("invalid"))))) -> invalid | U615: =IF(E606=1,"January",IF(E606=2,"February",("invalid"))) -> January | V615: =IF(M615="",M614,M615) -> 0.2424 | W615: =IF(C615=1,"winter",("invalid")) -> winter
A616: 615 | B616: 40571 | C616: 1 | D616: 0 | E616: 1 | F616: 20 | G616: FALSE | H616: 5 | I616: Friday | J616: 2 | K616: Cloudy | L616: 0.24 | M616: 0.2273 | N616: 0.7 | O616: 0.194 | P616: 1 | Q616: 61 | R616: 62 | T616: =IF(K602=1,"Clear",IF(K602=2,"Cloudy",IF(K602=3,"Light Rain",IF(K602=4,"Heavy Rain",("invalid"))))) -> invalid | U616: =IF(E607=1,"January",IF(E607=2,"February",("invalid"))) -> January | V616: =IF(M616="",M615,M616) -> 0.2273 | W616: =IF(C616=1,"winter",("invalid")) -> winter
A617: 616 | B617: 40571 | C617: 1 | D617: 0 | E617: 1 | F617: 21 | G617: FALSE | H617: 5 | I617: Friday | J617: 2 | K617: Cloudy | L617: 0.22 | M617: 0.2273 | N617: 0.75 | O617: 0.1343 | P617: 1 | Q617: 57 | R617: 58 | T617: =IF(K603=1,"Clear",IF(K603=2,"Cloudy",IF(K603=3,"Light Rain",IF(K603=4,"Heavy Rain",("invalid"))))) -> invalid | U617: =IF(E608=1,"January",IF(E608=2,"February",("invalid"))) -> January | V617: =IF(M617="",M616,M617) -> 0.2273 | W617: =IF(C617=1,"winter",("invalid")) -> winter
A618: 617 | B618: 40571 | C618: 1 | D618: 0 | E618: 1 | F618: 22 | G618: FALSE | H618: 5 | I618: Friday | J618: 1 | K618: Clear | L618: 0.24 | M618: 0.2121 | N618: 0.65 | O618: 0.3582 | P618: 0 | Q618: 26 | R618: 26 | T618: =IF(K604=1,"Clear",IF(K604=2,"Cloudy",IF(K604=3,"Light Rain",IF(K604=4,"Heavy Rain",("invalid"))))) -> invalid | U618: =IF(E609=1,"January",IF(E609=2,"February",("invalid"))) -> January | V618: =IF(M618="",M617,M618) -> 0.2121 | W618: =IF(C618=1,"winter",("invalid")) -> winter
A619: 618 | B619: 40571 | C619: 1 | D619: 0 | E619: 1 | F619: 23 | G619: FALSE | H619: 5 | I619: Friday | J619: 1 | K619: Clear | L619: 0.24 | M619: 0.2273 | N619: 0.6 | O619: 0.2239 | P619: 1 | Q619: 22 | R619: 23 | T619: =IF(K605=1,"Clear",IF(K605=2,"Cloudy",IF(K605=3,"Light Rain",IF(K605=4,"Heavy Rain",("invalid"))))) -> invalid | U619: =IF(E610=1,"January",IF(E610=2,"February",("invalid"))) -> January | V619: =IF(M619="",M618,M619) -> 0.2273 | W619: =IF(C619=1,"winter",("invalid")) -> winter
A620: 619 | B620: 40572 | C620: 1 | D620: 0 | E620: 1 | F620: 0 | G620: FALSE | H620: 6 | I620: Saturday | J620: 1 | K620: Clear | L620: 0.22 | M620: 0.197 | N620: 0.64 | O620: 0.3582 | P620: 2 | Q620: 26 | R620: 28 | T620: =IF(K606=1,"Clear",IF(K606=2,"Cloudy",IF(K606=3,"Light Rain",IF(K606=4,"Heavy Rain",("invalid"))))) -> invalid | U620: =IF(E611=1,"January",IF(E611=2,"February",("invalid"))) -> January | V620: =IF(M620="",M619,M620) -> 0.197 | W620: =IF(C620=1,"winter",("invalid")) -> winter
A621: 620 | B621: 40572 | C621: 1 | D621: 0 | E621: 1 | F621: 1 | G621: FALSE | H621: 6 | I621: Saturday | J621: 1 | K621: Clear | L621: 0.22 | M621: 0.2273 | N621: 0.64 | O621: 0.194 | P621: 0 | Q621: 20 | R621: 20 | T621: =IF(K607=1,"Clear",IF(K607=2,"Cloudy",IF(K607=3,"Light Rain",IF(K607=4,"Heavy Rain",("invalid"))))) -> invalid | U621: =IF(E612=1,"January",IF(E612=2,"February",("invalid"))) -> January | V621: =IF(M621="",M620,M621) -> 0.2273 | W621: =IF(C621=1,"winter",("invalid")) -> winter
